<?xml version="1.0" ?>
<sdf version='1.5'>
  <model name='adiona'>
    <link name='base_footprint'>
      <inertial>
        <pose>-0.074314 -0.025 0.116959 0 -0 0</pose>
        <mass>1.20304</mass>
        <inertia>
          <ixx>0.00633972</ixx>
          <ixy>3.07257e-08</ixy>
          <ixz>-0.000294403</ixz>
          <iyy>0.00923866</iyy>
          <iyz>2.1684e-18</iyz>
          <izz>0.0111795</izz>
        </inertia>
      </inertial>
      <collision name='base_footprint_fixed_joint_lump__base_link_collision'>
        <pose>0 0 0.1 0 -0 0</pose>
        <geometry>
          <mesh>
            <scale>1 1 1</scale>
            <uri>model://testurdf/models/adiona_description/meshes/base_link.STL</uri>
          </mesh>
        </geometry>
      </collision>
      <collision name='base_footprint_fixed_joint_lump__lidar_link_collision_1'>
        <pose>-0.02 -0.025 0.16 0 -0 0</pose>
        <geometry>
          <cylinder>
            <length>0.18</length>
            <radius>0.0508</radius>
          </cylinder>
        </geometry>
      </collision>
      <visual name='base_footprint_fixed_joint_lump__base_link_visual'>
        <pose>0 0 0.1 0 -0 0</pose>
        <geometry>
          <mesh>
            <scale>1 1 1</scale>
            <uri>model://testurdf/models/adiona_description/meshes/base_link.STL</uri>
          </mesh>
        </geometry>
      </visual>
      <visual name='base_footprint_fixed_joint_lump__lidar_link_visual_1'>
        <pose>-0.02 -0.025 0.16 0 -0 0</pose>
        <geometry>
          <cylinder>
            <length>0.02</length>
            <radius>0.02</radius>
          </cylinder>
        </geometry>
      </visual>
    </link>
    <joint name='bl_joint' type='revolute'>
      <pose relative_to='base_footprint'>-0.26808 0.17 0.011428 0 -0 0</pose>
      <parent>base_footprint</parent>
      <child>bl_link</child>
      <axis>
        <xyz>0 1 0</xyz>
        <limit>
          <lower>-3.1415</lower>
          <upper>3.1415</upper>
          <effort>30</effort>
          <velocity>5</velocity>
        </limit>
        <dynamics>
          <spring_reference>0</spring_reference>
          <spring_stiffness>0</spring_stiffness>
        </dynamics>
      </axis>
    </joint>
    <link name='bl_link'>
      <pose relative_to='bl_joint'>0 0 0 0 -0 0</pose>
      <inertial>
        <pose>-0 0.02 -0 0 -0 0</pose>
        <mass>0.251327</mass>
        <inertia>
          <ixx>0.000162316</ixx>
          <ixy>-1.22285e-20</ixy>
          <ixz>-3.34719e-20</ixz>
          <iyy>0.000257611</iyy>
          <iyz>-3.82142e-20</iyz>
          <izz>0.000162316</izz>
        </inertia>
      </inertial>
      <collision name='bl_link_collision'>
        <pose>0 0 0 0 -0 0</pose>
        <geometry>
          <mesh>
            <scale>1 1 1</scale>
            <uri>model://testurdf/models/adiona_description/meshes/wheel.STL</uri>
          </mesh>
        </geometry>
      </collision>
      <visual name='bl_link_visual'>
        <pose>0 0 0 0 -0 0</pose>
        <geometry>
          <mesh>
            <scale>1 1 1</scale>
            <uri>model://testurdf/models/adiona_description/meshes/wheel.STL</uri>
          </mesh>
        </geometry>
      </visual>
    </link>
    <joint name='br_joint' type='revolute'>
      <pose relative_to='base_footprint'>-0.26808 -0.18 0.011428 0 -0 0</pose>
      <parent>base_footprint</parent>
      <child>br_link</child>
      <axis>
        <xyz>0 1 0</xyz>
        <limit>
          <lower>-3.1415</lower>
          <upper>3.1415</upper>
          <effort>30</effort>
          <velocity>5</velocity>
        </limit>
        <dynamics>
          <spring_reference>0</spring_reference>
          <spring_stiffness>0</spring_stiffness>
        </dynamics>
      </axis>
    </joint>
    <link name='br_link'>
      <pose relative_to='br_joint'>0 0 0 0 -0 0</pose>
      <inertial>
        <pose>-0 -0.02 -0 0 -0 0</pose>
        <mass>0.251327</mass>
        <inertia>
          <ixx>0.000162316</ixx>
          <ixy>-4.87922e-20</ixy>
          <ixz>3.99022e-21</ixz>
          <iyy>0.000257611</iyy>
          <iyz>-5.5751e-20</iyz>
          <izz>0.000162316</izz>
        </inertia>
      </inertial>
      <collision name='br_link_collision'>
        <pose>0 0 0 0 -0 0</pose>
        <geometry>
          <mesh>
            <scale>1 1 1</scale>
            <uri>model://testurdf/models/adiona_description/meshes/wheel.STL</uri>
          </mesh>
        </geometry>
      </collision>
      <visual name='br_link_visual'>
        <pose>0 0 0 0 -0 0</pose>
        <geometry>
          <mesh>
            <scale>1 1 1</scale>
            <uri>model://testurdf/models/adiona_description/meshes/wheel.STL</uri>
          </mesh>
        </geometry>
      </visual>
    </link>
    <joint name='fl_joint' type='revolute'>
      <pose relative_to='base_footprint'>0.10808 0.17 0.011428 0 -0 0</pose>
      <parent>base_footprint</parent>
      <child>fl_link</child>
      <axis>
        <xyz>0 1 0</xyz>
        <limit>
          <lower>-3.1415</lower>
          <upper>3.1415</upper>
          <effort>30</effort>
          <velocity>5</velocity>
        </limit>
        <dynamics>
          <spring_reference>0</spring_reference>
          <spring_stiffness>0</spring_stiffness>
        </dynamics>
      </axis>
    </joint>
    <link name='fl_link'>
      <pose relative_to='fl_joint'>0 0 0 0 -0 0</pose>
      <inertial>
        <pose>0 0.02 -0 0 -0 0</pose>
        <mass>0.251327</mass>
        <inertia>
          <ixx>0.000162316</ixx>
          <ixy>-3.73266e-20</ixy>
          <ixz>-1.33852e-20</ixz>
          <iyy>0.000257611</iyy>
          <iyz>-5.5669e-20</iyz>
          <izz>0.000162316</izz>
        </inertia>
      </inertial>
      <collision name='fl_link_collision'>
        <pose>0 0 0 0 -0 0</pose>
        <geometry>
          <mesh>
            <scale>1 1 1</scale>
            <uri>model://testurdf/models/adiona_description/meshes/wheel.STL</uri>
          </mesh>
        </geometry>
      </collision>
      <visual name='fl_link_visual'>
        <pose>0 0 0 0 -0 0</pose>
        <geometry>
          <mesh>
            <scale>1 1 1</scale>
            <uri>model://testurdf/models/adiona_description/meshes/wheel.STL</uri>
          </mesh>
        </geometry>
      </visual>
    </link>
    <joint name='fr_joint' type='revolute'>
      <pose relative_to='base_footprint'>0.10808 -0.18 0.011428 0 -0 0</pose>
      <parent>base_footprint</parent>
      <child>fr_link</child>
      <axis>
        <xyz>0 1 0</xyz>
        <limit>
          <lower>-3.1415</lower>
          <upper>3.1415</upper>
          <effort>30</effort>
          <velocity>5</velocity>
        </limit>
        <dynamics>
          <spring_reference>0</spring_reference>
          <spring_stiffness>0</spring_stiffness>
        </dynamics>
      </axis>
    </joint>
    <link name='fr_link'>
      <pose relative_to='fr_joint'>0 0 0 0 -0 0</pose>
      <inertial>
        <pose>0 -0.02 -0 0 -0 0</pose>
        <mass>0.251327</mass>
        <inertia>
          <ixx>0.000162316</ixx>
          <ixy>-3.04983e-20</ixy>
          <ixz>-7.31774e-21</ixz>
          <iyy>0.000257611</iyy>
          <iyz>-5.02865e-20</iyz>
          <izz>0.000162316</izz>
        </inertia>
      </inertial>
      <collision name='fr_link_collision'>
        <pose>0 0 0 0 -0 0</pose>
        <geometry>
          <mesh>
            <scale>1 1 1</scale>
            <uri>model://testurdf/models/adiona_description/meshes/wheel.STL</uri>
          </mesh>
        </geometry>
      </collision>
      <visual name='fr_link_visual'>
        <pose>0 0 0 0 -0 0</pose>
        <geometry>
          <mesh>
            <scale>1 1 1</scale>
            <uri>model://testurdf/models/adiona_description/meshes/wheel.STL</uri>
          </mesh>
        </geometry>
      </visual>
    </link>
  </model>
</sdf>
