<?xml version="1.0" encoding="utf-8"?>
<!-- This URDF was automatically created by SolidWorks to URDF Exporter! Originally created by Stephen Brawner (brawner@gmail.com) 
     Commit Version: 1.6.0-1-g15f4949  Build Version: 1.6.7594.29634
     For more information, please see http://wiki.ros.org/sw_urdf_exporter -->
<robot
  name="URDF_Adiona_Mk1">
  <link
    name="base_link">
    <inertial>
      <origin
        xyz="0.00125192417980186 2.47071000591026E-17 0.00259134642385284"
        rpy="0 0 0" />
      <mass
        value="0.0566340469411713" />
      <inertia
        ixx="4.27996691887376E-05"
        ixy="2.65853182210332E-21"
        ixz="9.52567117930202E-06"
        iyy="0.000216957417987801"
        iyz="1.25975722966879E-20"
        izz="0.000253434352115576" />
    </inertial>
    <visual>
      <origin
        xyz="0 0 0"
        rpy="0 0 0" />
      <geometry>
        <mesh
          filename="package://URDF_Adiona_Mk1/meshes/base_link.STL" />
      </geometry>
      <material
        name="">
        <color
          rgba="0.592156862745098 0.666666666666667 0.682352941176471 1" />
      </material>
    </visual>
    <collision>
      <origin
        xyz="0 0 0"
        rpy="0 0 0" />
      <geometry>
        <mesh
          filename="package://URDF_Adiona_Mk1/meshes/base_link.STL" />
      </geometry>
    </collision>
  </link>
  <link
    name="linkfl">
    <inertial>
      <origin
        xyz="0 -0.0101224327659074 1.04083408558608E-17"
        rpy="0 0 0" />
      <mass
        value="0.0240560040517924" />
      <inertia
        ixx="3.06718879483244E-06"
        ixy="5.65835137466988E-23"
        ixz="3.34843896725363E-23"
        iyy="4.56991204419881E-06"
        iyz="-5.8007603698938E-22"
        izz="3.06718879483244E-06" />
    </inertial>
    <visual>
      <origin
        xyz="0 0 0"
        rpy="0 0 0" />
      <geometry>
        <mesh
          filename="package://URDF_Adiona_Mk1/meshes/linkfl.STL" />
      </geometry>
      <material
        name="">
        <color
          rgba="0.792156862745098 0.819607843137255 0.933333333333333 1" />
      </material>
    </visual>
    <collision>
      <origin
        xyz="0 0 0"
        rpy="0 0 0" />
      <geometry>
        <mesh
          filename="package://URDF_Adiona_Mk1/meshes/linkfl.STL" />
      </geometry>
    </collision>
  </link>
  <joint
    name="fljoint"
    type="continuous">
    <origin
      xyz="0.088745 0.057 -0.005"
      rpy="0 0 0" />
    <parent
      link="base_link" />
    <child
      link="linkfl" />
    <axis
      xyz="0 1 0" />
    <limit
      effort="1"
      velocity="1" />
  </joint>
  <link
    name="linkfr">
    <inertial>
      <origin
        xyz="-2.77555756156289E-17 0.0101224327659074 -6.93889390390723E-18"
        rpy="0 0 0" />
      <mass
        value="0.0240560040517924" />
      <inertia
        ixx="3.06718879483244E-06"
        ixy="9.33896055017013E-23"
        ixz="-2.68363832488294E-23"
        iyy="4.56991204419882E-06"
        iyz="-5.60006063078217E-22"
        izz="3.06718879483244E-06" />
    </inertial>
    <visual>
      <origin
        xyz="0 0 0"
        rpy="0 0 0" />
      <geometry>
        <mesh
          filename="package://URDF_Adiona_Mk1/meshes/linkfr.STL" />
      </geometry>
      <material
        name="">
        <color
          rgba="0.792156862745098 0.819607843137255 0.933333333333333 1" />
      </material>
    </visual>
    <collision>
      <origin
        xyz="0 0 0"
        rpy="0 0 0" />
      <geometry>
        <mesh
          filename="package://URDF_Adiona_Mk1/meshes/linkfr.STL" />
      </geometry>
    </collision>
  </link>
  <joint
    name="frjoint"
    type="continuous">
    <origin
      xyz="0.088745 -0.057 -0.005"
      rpy="0 0 0" />
    <parent
      link="base_link" />
    <child
      link="linkfr" />
    <axis
      xyz="0 1 0" />
    <limit
      effort="1"
      velocity="1" />
  </joint>
  <link
    name="linkbl">
    <inertial>
      <origin
        xyz="3.46944695195361E-18 -0.0101224327659074 0"
        rpy="0 0 0" />
      <mass
        value="0.0240560040517924" />
      <inertia
        ixx="3.06718879483244E-06"
        ixy="-1.33556345940005E-23"
        ixz="-5.71758979329823E-23"
        iyy="4.56991204419881E-06"
        iyz="-4.81042835972897E-22"
        izz="3.06718879483244E-06" />
    </inertial>
    <visual>
      <origin
        xyz="0 0 0"
        rpy="0 0 0" />
      <geometry>
        <mesh
          filename="package://URDF_Adiona_Mk1/meshes/linkbl.STL" />
      </geometry>
      <material
        name="">
        <color
          rgba="0.792156862745098 0.819607843137255 0.933333333333333 1" />
      </material>
    </visual>
    <collision>
      <origin
        xyz="0 0 0"
        rpy="0 0 0" />
      <geometry>
        <mesh
          filename="package://URDF_Adiona_Mk1/meshes/linkbl.STL" />
      </geometry>
    </collision>
  </link>
  <joint
    name="bljoint"
    type="continuous">
    <origin
      xyz="-0.069755 0.057 -0.005"
      rpy="0 0 0" />
    <parent
      link="base_link" />
    <child
      link="linkbl" />
    <axis
      xyz="0 1 0" />
    <limit
      effort="1"
      velocity="1" />
  </joint>
  <link
    name="linkbr">
    <inertial>
      <origin
        xyz="3.46944695195361E-18 0.0101224327659074 -3.46944695195361E-18"
        rpy="0 0 0" />
      <mass
        value="0.0240560040517924" />
      <inertia
        ixx="3.06718879483244E-06"
        ixy="9.97164617365422E-24"
        ixz="-3.86965430309963E-23"
        iyy="4.56991204419881E-06"
        iyz="-5.13349517251122E-22"
        izz="3.06718879483244E-06" />
    </inertial>
    <visual>
      <origin
        xyz="0 0 0"
        rpy="0 0 0" />
      <geometry>
        <mesh
          filename="package://URDF_Adiona_Mk1/meshes/linkbr.STL" />
      </geometry>
      <material
        name="">
        <color
          rgba="0.792156862745098 0.819607843137255 0.933333333333333 1" />
      </material>
    </visual>
    <collision>
      <origin
        xyz="0 0 0"
        rpy="0 0 0" />
      <geometry>
        <mesh
          filename="package://URDF_Adiona_Mk1/meshes/linkbr.STL" />
      </geometry>
    </collision>
  </link>
  <joint
    name="brjoint"
    type="continuous">
    <origin
      xyz="-0.069755 -0.057 -0.005"
      rpy="0 0 0" />
    <parent
      link="base_link" />
    <child
      link="linkbr" />
    <axis
      xyz="0 1 0" />
    <limit
      effort="1"
      velocity="1" />
  </joint>
</robot>